<?xml version="1.0"?>
<robot xmlns:xacro="http://www.ros.org/wiki/xacro" name="example">
    <xacro:include filename="gazebo_full.xacro" />

    <link name="dummy_link"/>
    
    <joint name="fixed_dummy_joint" type="fixed">
        <parent link="dummy_link"/>
        <child link="base_link"/>
        <origin xyz="0 0 0" rpy="0 0 0"/>
    </joint>

    <link name='base_link'>
        <inertial>
        <mass value='0.12' />
        <inertia ixx='0.01' ixy='0' ixz='0' iyy='0.01' iyz='0' izz='0.01' />
        </inertial>
    </link>
    <joint name='j1' type='continuous'>
        <parent link='base_link'/>
        <child link='end_effector'/>
        <origin xyz='0 0 1' rpy='0 0 0'/>
    </joint>
    <link name='end_effector'>
        <inertial>
        <mass value='0.12' />
        <inertia ixx='0.01' ixy='0' ixz='0' iyy='0.01' iyz='0' izz='0.01' />
        </inertial>
    </link>
    <gazebo reference='j1'>
        <springReference>0.5</springReference>
        <springStiffness>0.25</springStiffness>
    </gazebo>

    
    

</robot>
